Traceback (most recent call last):
  File "/uufs/chpc.utah.edu/common/home/u1419632/miniconda3/envs/condenv/lib/python3.11/site-packages/huggingface_hub/utils/_errors.py", line 261, in hf_raise_for_status
    response.raise_for_status()
  File "/uufs/chpc.utah.edu/common/home/u1419632/miniconda3/envs/condenv/lib/python3.11/site-packages/requests/models.py", line 1021, in raise_for_status
    raise HTTPError(http_error_msg, response=self)
requests.exceptions.HTTPError: 401 Client Error: Unauthorized for url: https://huggingface.co/meta-llama/Llama-2-7b-chat-hf/resolve/main/config.json

The above exception was the direct cause of the following exception:

Traceback (most recent call last):
  File "/uufs/chpc.utah.edu/common/home/u1419632/miniconda3/envs/condenv/lib/python3.11/site-packages/transformers/utils/hub.py", line 430, in cached_file
    resolved_file = hf_hub_download(
                    ^^^^^^^^^^^^^^^^
  File "/uufs/chpc.utah.edu/common/home/u1419632/miniconda3/envs/condenv/lib/python3.11/site-packages/huggingface_hub/utils/_validators.py", line 118, in _inner_fn
    return fn(*args, **kwargs)
           ^^^^^^^^^^^^^^^^^^^
  File "/uufs/chpc.utah.edu/common/home/u1419632/miniconda3/envs/condenv/lib/python3.11/site-packages/huggingface_hub/file_download.py", line 1195, in hf_hub_download
    metadata = get_hf_file_metadata(
               ^^^^^^^^^^^^^^^^^^^^^
  File "/uufs/chpc.utah.edu/common/home/u1419632/miniconda3/envs/condenv/lib/python3.11/site-packages/huggingface_hub/utils/_validators.py", line 118, in _inner_fn
    return fn(*args, **kwargs)
           ^^^^^^^^^^^^^^^^^^^
  File "/uufs/chpc.utah.edu/common/home/u1419632/miniconda3/envs/condenv/lib/python3.11/site-packages/huggingface_hub/file_download.py", line 1541, in get_hf_file_metadata
    hf_raise_for_status(r)
  File "/uufs/chpc.utah.edu/common/home/u1419632/miniconda3/envs/condenv/lib/python3.11/site-packages/huggingface_hub/utils/_errors.py", line 277, in hf_raise_for_status
    raise GatedRepoError(message, response) from e
huggingface_hub.utils._errors.GatedRepoError: 401 Client Error. (Request ID: Root=1-6567e135-5b3c9ce94a37beed14969b0e;5713b61b-bfb8-41c2-bcf8-a5c448600cad)

Cannot access gated repo for url https://huggingface.co/meta-llama/Llama-2-7b-chat-hf/resolve/main/config.json.
Repo model meta-llama/Llama-2-7b-chat-hf is gated. You must be authenticated to access it.

The above exception was the direct cause of the following exception:

Traceback (most recent call last):
  File "/uufs/chpc.utah.edu/common/home/u1419632/local-explainability-project/run_tcav.py", line 136, in <module>
    model = LlamaCompletionConditionalLikelihood.from_pretrained(args.model_id)
            ^^^^^^^^^^^^^^^^^^^^^^^^^^^^^^^^^^^^^^^^^^^^^^^^^^^^^^^^^^^^^^^^^^^
  File "/uufs/chpc.utah.edu/common/home/u1419632/local-explainability-project/run_tcav.py", line 24, in from_pretrained
    llama = LlamaForCausalLM.from_pretrained(model_name_or_path)
            ^^^^^^^^^^^^^^^^^^^^^^^^^^^^^^^^^^^^^^^^^^^^^^^^^^^^
  File "/uufs/chpc.utah.edu/common/home/u1419632/miniconda3/envs/condenv/lib/python3.11/site-packages/transformers/modeling_utils.py", line 2600, in from_pretrained
    resolved_config_file = cached_file(
                           ^^^^^^^^^^^^
  File "/uufs/chpc.utah.edu/common/home/u1419632/miniconda3/envs/condenv/lib/python3.11/site-packages/transformers/utils/hub.py", line 445, in cached_file
    raise EnvironmentError(
OSError: You are trying to access a gated repo.
Make sure to request access at https://huggingface.co/meta-llama/Llama-2-7b-chat-hf and pass a token having permission to this repo either by logging in with `huggingface-cli login` or by passing `token=<your_token>`.
